<?xml version="1.0" ?>
<robot name="s1110837-finaltopics" xmlns:xacro="http://www.ros.org/wiki/xacro">

<xacro:include filename="$(find s1110837-finaltopics_description)/urdf/materials.xacro" />
<xacro:include filename="$(find s1110837-finaltopics_description)/urdf/s1110837-finaltopics.trans" />
<xacro:include filename="$(find s1110837-finaltopics_description)/urdf/s1110837-finaltopics.gazebo" />
<link name="base_link">
  <inertial>
    <origin xyz="5.63872037916951e-14 -0.0009545686939231486 0.06478515956991303" rpy="0 0 0"/>
    <mass value="0.38533002960155827"/>
    <inertia ixx="0.001697" iyy="0.00164" izz="0.002399" ixy="-0.0" iyz="-3.4e-05" ixz="0.0"/>
  </inertial>
  <visual>
    <origin xyz="0 0 0" rpy="0 0 0"/>
    <geometry>
      <mesh filename="package://s1110837-finaltopics_description/meshes/base_link.stl" scale="0.001 0.001 0.001"/>
    </geometry>
    <material name="silver"/>
  </visual>
  <collision>
    <origin xyz="0 0 0" rpy="0 0 0"/>
    <geometry>
      <mesh filename="package://s1110837-finaltopics_description/meshes/base_link.stl" scale="0.001 0.001 0.001"/>
    </geometry>
  </collision>
</link>

<link name="left_wheel_1">
  <inertial>
    <origin xyz="-0.012499999999999997 -1.1580046200244058e-17 0.0" rpy="0 0 0"/>
    <mass value="0.2788163480060941"/>
    <inertia ixx="0.000349" iyy="0.000189" izz="0.000189" ixy="-0.0" iyz="-0.0" ixz="0.0"/>
  </inertial>
  <visual>
    <origin xyz="0.1 -0.0 -0.05" rpy="0 0 0"/>
    <geometry>
      <mesh filename="package://s1110837-finaltopics_description/meshes/left_wheel_1.stl" scale="0.001 0.001 0.001"/>
    </geometry>
    <material name="silver"/>
  </visual>
  <collision>
    <origin xyz="0.1 -0.0 -0.05" rpy="0 0 0"/>
    <geometry>
      <mesh filename="package://s1110837-finaltopics_description/meshes/left_wheel_1.stl" scale="0.001 0.001 0.001"/>
    </geometry>
  </collision>
</link>

<link name="right_wheel_1">
  <inertial>
    <origin xyz="0.012499999999999997 -5.790023100122029e-18 0.0" rpy="0 0 0"/>
    <mass value="0.2788163480060941"/>
    <inertia ixx="0.000349" iyy="0.000189" izz="0.000189" ixy="0.0" iyz="0.0" ixz="-0.0"/>
  </inertial>
  <visual>
    <origin xyz="-0.1 -0.0 -0.05" rpy="0 0 0"/>
    <geometry>
      <mesh filename="package://s1110837-finaltopics_description/meshes/right_wheel_1.stl" scale="0.001 0.001 0.001"/>
    </geometry>
    <material name="silver"/>
  </visual>
  <collision>
    <origin xyz="-0.1 -0.0 -0.05" rpy="0 0 0"/>
    <geometry>
      <mesh filename="package://s1110837-finaltopics_description/meshes/right_wheel_1.stl" scale="0.001 0.001 0.001"/>
    </geometry>
  </collision>
</link>

<link name="lidar_1">
  <inertial>
    <origin xyz="0.0 0.0 0.012499999999999997" rpy="0 0 0"/>
    <mass value="0.21166480503561222"/>
    <inertia ixx="7.6e-05" iyy="7.6e-05" izz="0.00013" ixy="-0.0" iyz="0.0" ixz="-0.0"/>
  </inertial>
  <visual>
    <origin xyz="-0.0 0.05 -0.11" rpy="0 0 0"/>
    <geometry>
      <mesh filename="package://s1110837-finaltopics_description/meshes/lidar_1.stl" scale="0.001 0.001 0.001"/>
    </geometry>
    <material name="silver"/>
  </visual>
  <collision>
    <origin xyz="-0.0 0.05 -0.11" rpy="0 0 0"/>
    <geometry>
      <mesh filename="package://s1110837-finaltopics_description/meshes/lidar_1.stl" scale="0.001 0.001 0.001"/>
    </geometry>
  </collision>
</link>

<link name="camera_1">
  <inertial>
    <origin xyz="0.0 -0.002500000000000016 0.0" rpy="0 0 0"/>
    <mass value="0.0034243359924128747"/>
    <inertia ixx="0.0" iyy="0.0" izz="0.0" ixy="-0.0" iyz="0.0" ixz="0.0"/>
  </inertial>
  <visual>
    <origin xyz="-0.0 0.1 -0.05" rpy="0 0 0"/>
    <geometry>
      <mesh filename="package://s1110837-finaltopics_description/meshes/camera_1.stl" scale="0.001 0.001 0.001"/>
    </geometry>
    <material name="silver"/>
  </visual>
  <collision>
    <origin xyz="-0.0 0.1 -0.05" rpy="0 0 0"/>
    <geometry>
      <mesh filename="package://s1110837-finaltopics_description/meshes/camera_1.stl" scale="0.001 0.001 0.001"/>
    </geometry>
  </collision>
</link>

<joint name="Revolute 1" type="continuous">
  <origin xyz="-0.1 0.0 0.05" rpy="0 0 0"/>
  <parent link="base_link"/>
  <child link="left_wheel_1"/>
  <axis xyz="1.0 0.0 0.0"/>
</joint>

<joint name="Revolute 2" type="continuous">
  <origin xyz="0.1 0.0 0.05" rpy="0 0 0"/>
  <parent link="base_link"/>
  <child link="right_wheel_1"/>
  <axis xyz="1.0 0.0 0.0"/>
</joint>

<joint name="Rigid 3" type="fixed">
  <origin xyz="0.0 -0.05 0.11" rpy="0 0 0"/>
  <parent link="base_link"/>
  <child link="lidar_1"/>
</joint>

<joint name="Rigid 4" type="fixed">
  <origin xyz="0.0 -0.1 0.05" rpy="0 0 -1.5708"/>
  <parent link="base_link"/>
  <child link="camera_1"/>
</joint>

</robot>
